[2023-12-10 16:45:22,644] INFO _log() L122  127.0.0.1 - - [10/Dec/2023 16:45:22] "POST /paciente HTTP/1.1" 500 - - call_trace=/usr/lib/python3/dist-packages/werkzeug/_internal.py L122 
[2023-12-10 16:45:54,434] INFO _log() L122   * Detected change in '/mnt/c/Users/robso/OneDrive/Área de Trabalho/MVP_04/backend/model/paciente.py', reloading - call_trace=/usr/lib/python3/dist-packages/werkzeug/_internal.py L122 
[2023-12-10 16:45:59,186] WARNING predict() L163  Erro ao adicionar paciente 'Pedro', Não foi possível salvar novo item :/ - call_trace=/mnt/c/Users/robso/OneDrive/Área de Trabalho/MVP_04/backend/app.py L163 
[2023-12-10 16:45:59,192] INFO _log() L122  127.0.0.1 - - [10/Dec/2023 16:45:59] "POST /paciente HTTP/1.1" 400 - - call_trace=/usr/lib/python3/dist-packages/werkzeug/_internal.py L122 
[2023-12-10 16:46:21,653] INFO _log() L122  127.0.0.1 - - [10/Dec/2023 16:46:21] "GET /openapi/swagger HTTP/1.1" 200 - - call_trace=/usr/lib/python3/dist-packages/werkzeug/_internal.py L122 
[2023-12-10 16:46:22,433] INFO _log() L122  127.0.0.1 - - [10/Dec/2023 16:46:22] "GET /openapi/openapi.json HTTP/1.1" 200 - - call_trace=/usr/lib/python3/dist-packages/werkzeug/_internal.py L122 
[2023-12-10 16:46:28,755] WARNING predict() L163  Erro ao adicionar paciente 'Pedro', Não foi possível salvar novo item :/ - call_trace=/mnt/c/Users/robso/OneDrive/Área de Trabalho/MVP_04/backend/app.py L163 
[2023-12-10 16:46:28,756] INFO _log() L122  127.0.0.1 - - [10/Dec/2023 16:46:28] "POST /paciente HTTP/1.1" 400 - - call_trace=/usr/lib/python3/dist-packages/werkzeug/_internal.py L122 
[2023-12-10 16:47:16,325] INFO _log() L122   * Detected change in '/mnt/c/Users/robso/OneDrive/Área de Trabalho/MVP_04/backend/app.py', reloading - call_trace=/usr/lib/python3/dist-packages/werkzeug/_internal.py L122 
[2023-12-10 16:47:19,884] INFO _log() L122   * Detected change in '/mnt/c/Users/robso/OneDrive/Área de Trabalho/MVP_04/backend/app.py', reloading - call_trace=/usr/lib/python3/dist-packages/werkzeug/_internal.py L122 
[2023-12-10 16:47:36,673] INFO _log() L122   * Detected change in '/mnt/c/Users/robso/OneDrive/Área de Trabalho/MVP_04/backend/model/paciente.py', reloading - call_trace=/usr/lib/python3/dist-packages/werkzeug/_internal.py L122 
[2023-12-10 16:47:56,704] INFO _log() L122   * Detected change in '/mnt/c/Users/robso/OneDrive/Área de Trabalho/MVP_04/backend/schemas/paciente_schema.py', reloading - call_trace=/usr/lib/python3/dist-packages/werkzeug/_internal.py L122 
[2023-12-10 16:48:07,196] WARNING predict() L161  Erro ao adicionar paciente 'Pedro', Não foi possível salvar novo item :/ - call_trace=/mnt/c/Users/robso/OneDrive/Área de Trabalho/MVP_04/backend/app.py L161 
[2023-12-10 16:48:07,203] INFO _log() L122  127.0.0.1 - - [10/Dec/2023 16:48:07] "POST /paciente HTTP/1.1" 400 - - call_trace=/usr/lib/python3/dist-packages/werkzeug/_internal.py L122 
[2023-12-10 16:49:57,056] INFO _log() L122   * Detected change in '/mnt/c/Users/robso/OneDrive/Área de Trabalho/MVP_04/backend/app.py', reloading - call_trace=/usr/lib/python3/dist-packages/werkzeug/_internal.py L122 
[2023-12-10 16:50:54,601] WARNING predict() L161  Erro ao adicionar paciente 'Pedro', Não foi possível salvar novo item :/ - call_trace=/mnt/c/Users/robso/OneDrive/Área de Trabalho/MVP_04/backend/app.py L161 
[2023-12-10 16:50:54,609] INFO _log() L122  127.0.0.1 - - [10/Dec/2023 16:50:54] "POST /paciente HTTP/1.1" 400 - - call_trace=/usr/lib/python3/dist-packages/werkzeug/_internal.py L122 
[2023-12-10 16:51:48,193] INFO _log() L122  127.0.0.1 - - [10/Dec/2023 16:51:48] "GET /openapi/swagger HTTP/1.1" 200 - - call_trace=/usr/lib/python3/dist-packages/werkzeug/_internal.py L122 
[2023-12-10 16:51:49,433] INFO _log() L122  127.0.0.1 - - [10/Dec/2023 16:51:49] "GET /openapi/openapi.json HTTP/1.1" 200 - - call_trace=/usr/lib/python3/dist-packages/werkzeug/_internal.py L122 
[2023-12-10 16:52:10,139] WARNING predict() L161  Erro ao adicionar paciente 'Pedro', Não foi possível salvar novo item :/ - call_trace=/mnt/c/Users/robso/OneDrive/Área de Trabalho/MVP_04/backend/app.py L161 
[2023-12-10 16:52:10,139] INFO _log() L122  127.0.0.1 - - [10/Dec/2023 16:52:10] "POST /paciente HTTP/1.1" 400 - - call_trace=/usr/lib/python3/dist-packages/werkzeug/_internal.py L122 
[2023-12-10 16:57:23,100] INFO _log() L122  127.0.0.1 - - [10/Dec/2023 16:57:23] "GET /openapi/swagger HTTP/1.1" 200 - - call_trace=/usr/lib/python3/dist-packages/werkzeug/_internal.py L122 
[2023-12-10 16:57:23,537] INFO _log() L122  127.0.0.1 - - [10/Dec/2023 16:57:23] "GET /openapi/openapi.json HTTP/1.1" 200 - - call_trace=/usr/lib/python3/dist-packages/werkzeug/_internal.py L122 
[2023-12-10 16:57:32,440] WARNING predict() L161  Erro ao adicionar paciente 'Pedro', Não foi possível salvar novo item :/ - call_trace=/mnt/c/Users/robso/OneDrive/Área de Trabalho/MVP_04/backend/app.py L161 
[2023-12-10 16:57:32,451] INFO _log() L122  127.0.0.1 - - [10/Dec/2023 16:57:32] "POST /paciente HTTP/1.1" 400 - - call_trace=/usr/lib/python3/dist-packages/werkzeug/_internal.py L122 
[2023-12-10 17:01:14,439] INFO _log() L122  127.0.0.1 - - [10/Dec/2023 17:01:14] "GET /openapi/swagger HTTP/1.1" 200 - - call_trace=/usr/lib/python3/dist-packages/werkzeug/_internal.py L122 
[2023-12-10 17:01:15,451] INFO _log() L122  127.0.0.1 - - [10/Dec/2023 17:01:15] "GET /openapi/openapi.json HTTP/1.1" 200 - - call_trace=/usr/lib/python3/dist-packages/werkzeug/_internal.py L122 
[2023-12-10 17:01:24,134] WARNING predict() L161  Erro ao adicionar paciente 'Pedro', Não foi possível salvar novo item :/ - call_trace=/mnt/c/Users/robso/OneDrive/Área de Trabalho/MVP_04/backend/app.py L161 
[2023-12-10 17:01:24,141] INFO _log() L122  127.0.0.1 - - [10/Dec/2023 17:01:24] "POST /paciente HTTP/1.1" 400 - - call_trace=/usr/lib/python3/dist-packages/werkzeug/_internal.py L122 
[2023-12-10 17:03:36,903] INFO _log() L122   * Detected change in '/mnt/c/Users/robso/OneDrive/Área de Trabalho/MVP_04/backend/model/modelo.py', reloading - call_trace=/usr/lib/python3/dist-packages/werkzeug/_internal.py L122 
[2023-12-10 17:04:00,584] WARNING predict() L161  Erro ao adicionar paciente 'Pedro', Não foi possível salvar novo item :/ - call_trace=/mnt/c/Users/robso/OneDrive/Área de Trabalho/MVP_04/backend/app.py L161 
[2023-12-10 17:04:00,596] INFO _log() L122  127.0.0.1 - - [10/Dec/2023 17:04:00] "POST /paciente HTTP/1.1" 400 - - call_trace=/usr/lib/python3/dist-packages/werkzeug/_internal.py L122 
[2023-12-10 17:04:26,646] INFO _log() L122   * Detected change in '/mnt/c/Users/robso/OneDrive/Área de Trabalho/MVP_04/backend/model/modelo.py', reloading - call_trace=/usr/lib/python3/dist-packages/werkzeug/_internal.py L122 
[2023-12-10 17:04:31,459] ERROR log_exception() L1890 Exception on /paciente [POST] - call_trace=/usr/lib/python3/dist-packages/flask/app.py L1890
Traceback (most recent call last):
  File "/usr/lib/python3/dist-packages/flask/app.py", line 2446, in wsgi_app
    response = self.full_dispatch_request()
  File "/usr/lib/python3/dist-packages/flask/app.py", line 1951, in full_dispatch_request
    rv = self.handle_user_exception(e)
  File "/usr/local/lib/python3.8/dist-packages/flask_cors/extension.py", line 176, in wrapped_function
    return cors_after_request(app.make_response(f(*args, **kwargs)))
  File "/usr/lib/python3/dist-packages/flask/app.py", line 1820, in handle_user_exception
    reraise(exc_type, exc_value, tb)
  File "/usr/lib/python3/dist-packages/flask/_compat.py", line 39, in reraise
    raise value
  File "/usr/lib/python3/dist-packages/flask/app.py", line 1949, in full_dispatch_request
    rv = self.dispatch_request()
  File "/usr/lib/python3/dist-packages/flask/app.py", line 1935, in dispatch_request
    return self.view_functions[rule.endpoint](**req.view_args)
  File "/usr/local/lib/python3.8/dist-packages/flask_openapi3/scaffold.py", line 117, in view_func
    response = func(**func_kwargs)
  File "/mnt/c/Users/robso/OneDrive/Área de Trabalho/MVP_04/backend/app.py", line 134, in predict
    outcome=Model.preditor(modelo, form)
  File "/mnt/c/Users/robso/OneDrive/Área de Trabalho/MVP_04/backend/model/modelo.py", line 32, in preditor
    diagnosis = model.predict(X_input)
  File "/usr/local/lib/python3.8/dist-packages/sklearn/neighbors/_classification.py", line 254, in predict
    probabilities = self.predict_proba(X)
  File "/usr/local/lib/python3.8/dist-packages/sklearn/neighbors/_classification.py", line 328, in predict_proba
    X = self._validate_data(
  File "/usr/local/lib/python3.8/dist-packages/sklearn/base.py", line 605, in _validate_data
    out = check_array(X, input_name="X", **check_params)
  File "/usr/local/lib/python3.8/dist-packages/sklearn/utils/validation.py", line 938, in check_array
    raise ValueError(
ValueError: Expected 2D array, got 1D array instead:
array=[1.799e+01 1.038e+01 1.228e+02 1.001e+03 1.184e-01 2.776e-01 3.001e-01
 1.471e-01 2.419e-01 7.871e-02 1.095e+00 9.053e-01 8.589e+00 1.534e+02
 6.399e-03 4.904e-02 5.373e-02 1.587e-02 3.003e-02 6.193e-03 2.538e+01
 1.733e+01 1.846e+02 2.019e+03 1.622e-01 6.656e-01 7.119e-01 2.654e-01
 4.601e-01 1.189e-01].
Reshape your data either using array.reshape(-1, 1) if your data has a single feature or array.reshape(1, -1) if it contains a single sample.
[2023-12-10 17:04:31,477] INFO _log() L122  127.0.0.1 - - [10/Dec/2023 17:04:31] "POST /paciente HTTP/1.1" 500 - - call_trace=/usr/lib/python3/dist-packages/werkzeug/_internal.py L122 
[2023-12-10 17:05:15,658] INFO _log() L122   * Detected change in '/mnt/c/Users/robso/OneDrive/Área de Trabalho/MVP_04/backend/model/modelo.py', reloading - call_trace=/usr/lib/python3/dist-packages/werkzeug/_internal.py L122 
[2023-12-10 17:05:18,087] WARNING predict() L161  Erro ao adicionar paciente 'Pedro', Não foi possível salvar novo item :/ - call_trace=/mnt/c/Users/robso/OneDrive/Área de Trabalho/MVP_04/backend/app.py L161 
